<?xml version="1.0" ?>
<!-- =================================================================================== -->
<!-- |    This document was autogenerated by xacro from /home/nico/catkin_test/src/armmp/armmp_description/urdf/armmp.xacro | -->
<!-- |    EDITING THIS FILE BY HAND IS NOT RECOMMENDED                                 | -->
<!-- =================================================================================== -->
<robot name="ur10e_robotiq">
    <!--
  Author: Nico Lingg
-->
    <!--
  Author: Kelsey Hawkins
  Contributers: Jimmy Da Silva, Ajit Krisshna N L, Muhammad Asif Rana
-->
    <link name="wheelchair_base_link">
        
<inertial>
            <origin rpy="0 0 0" xyz="-0.013975 0.051448 3.6862E-05" />
            <mass value="110.78" />
            <inertia ixx="0.50372" ixy="0.034645" ixz="0.00011003" iyy="3.112" iyz="0.00034085" izz="3.1694" />
        </inertial>

        <visual>
            <origin rpy="0 0 0" xyz="0 0 0" />
            <geometry>
                <mesh filename="wheelchair/meshes/base_link.STL" />
            </geometry>
            <material name="">
                <color rgba="1 1 1 1" />
            </material>
        </visual>
        <collision>
            <origin rpy="0 0 0" xyz="0 0 0" />
            <geometry>
                <mesh filename="wheelchair/meshes/base_link.STL" />
            </geometry>
        </collision>
    </link>
    <link name="wheelchair_drive_wheel_right">
        
<inertial>
            <origin rpy="0 0 0" xyz="-3.4907E-12 0.028895 1.236E-14" />
            <mass value="3.9607" />
            <inertia ixx="0.028179" ixy="3.3797E-15" ixz="-1.2302E-12" iyy="0.054226" iyz="-1.2741E-17" izz="0.028179" />
        </inertial>

        <visual>
            <origin rpy="0 0 0" xyz="0 0 0" />
            <geometry>
                <mesh filename="wheelchair/meshes/drive_wheel_right.STL" />
            </geometry>
            <material name="">
                <color rgba="0.29804 0.29804 0.29804 1" />
            </material>
        </visual>
        <collision>
            <origin rpy="0 0 0" xyz="0 0 0" />
            <geometry>
                <mesh filename="wheelchair/meshes/drive_wheel_right.STL" />
            </geometry>
        </collision>
    </link>
    <joint name="wheelchair_base_drive_wheel_right" type="fixed">
        <origin rpy="0 -0.8593 0" xyz="0 0.1995 0" />
        <parent link="wheelchair_base_link" />
        <child link="wheelchair_drive_wheel_right" />
        <axis xyz="0 1 0" />
    </joint>
    <link name="wheelchair_drive_wheel_left">
        
<inertial>
            <origin rpy="0 0 0" xyz="-3.4906E-12 0.028895 1.2374E-14" />
            <mass value="3.9607" />
            <inertia ixx="0.028179" ixy="3.3837E-15" ixz="-1.2302E-12" iyy="0.054226" iyz="-1.3611E-17" izz="0.028179" />
        </inertial>

        <visual>
            <origin rpy="0 0 0" xyz="0 0 0" />
            <geometry>
                <mesh filename="wheelchair/meshes/drive_wheel_left.STL" />
            </geometry>
            <material name="">
                <color rgba="0.29804 0.29804 0.29804 1" />
            </material>
        </visual>
        <collision>
            <origin rpy="0 0 0" xyz="0 0 0" />
            <geometry>
                <mesh filename="wheelchair/meshes/drive_wheel_left.STL" />
            </geometry>
        </collision>
    </link>
    <joint name="wheelchair_base_drive_wheel_left" type="fixed">
        <origin rpy="3.1416 -0.00012658 0" xyz="0 -0.1995 0" />
        <parent link="wheelchair_base_link" />
        <child link="wheelchair_drive_wheel_left" />
        <axis xyz="0 1 0" />
    </joint>
    <link name="wheelchair_castor_front_left">
        
<inertial>
            <origin rpy="0 0 0" xyz="0.010525 -0.0097266 7.7108E-08" />
            <mass value="0.20821" />
            <inertia ixx="0.00055537" ixy="8.8662E-05" ixz="8.9051E-11" iyy="0.00024751" iyz="1.6993E-09" izz="0.00042332" />
        </inertial>

        <visual>
            <origin rpy="0 0 0" xyz="0 0 0" />
            <geometry>
                <mesh filename="wheelchair/meshes/castor_front_left.STL" />
            </geometry>
            <material name="">
                <color rgba="0.19216 0.20392 0.20392 1" />
            </material>
        </visual>
        <collision>
            <origin rpy="0 0 0" xyz="0 0 0" />
            <geometry>
                <mesh filename="wheelchair/meshes/castor_front_left.STL" />
            </geometry>
        </collision>
    </link>
    <joint name="wheelchair_base_to_castor_front_left" type="fixed">
        <origin rpy="1.5708 0 3.1416" xyz="-0.38799 -0.17127 0" />
        <parent link="wheelchair_base_link" />
        <child link="wheelchair_castor_front_left" />
        <axis xyz="0 1 0" />
    </joint>
    <link name="wheelchair_front_wheel_left">
        
<inertial>
            <origin rpy="0 0 0" xyz="5.5511E-17 -4.3723E-13 1.5266E-16" />
            <mass value="1.1217" />
            <inertia ixx="0.0024847" ixy="2.8893E-15" ixz="3.8142E-20" iyy="0.0045217" iyz="-3.3191E-19" izz="0.0024847" />
        </inertial>

        <visual>
            <origin rpy="0 0 0" xyz="0 0 0" />
            <geometry>
                <mesh filename="wheelchair/meshes/front_wheel_left.STL" />
            </geometry>
            <material name="">
                <color rgba="0.89412 0.89412 0.89412 1" />
            </material>
        </visual>
        <collision>
            <origin rpy="0 0 0" xyz="0 0 0" />
            <geometry>
                <mesh filename="wheelchair/meshes/front_wheel_left.STL" />
            </geometry>
        </collision>
    </link>
    <joint name="wheelchair_castor_to_front_wheel_left" type="fixed">
        <origin rpy="1.5708 0 3.1416" xyz="0.026228 -0.0725 0" />
        <parent link="wheelchair_castor_front_left" />
        <child link="wheelchair_front_wheel_left" />
        <axis xyz="0 1 0" />
    </joint>
    <link name="wheelchair_castor_front_right">
        
<inertial>
            <origin rpy="0 0 0" xyz="0.010525 -0.0097266 7.7108E-08" />
            <mass value="0.59378" />
            <inertia ixx="0.0015838" ixy="0.00025285" ixz="2.5396E-10" iyy="0.00070588" iyz="4.8462E-09" izz="0.0012073" />
        </inertial>

        <visual>
            <origin rpy="0 0 0" xyz="0 0 0" />
            <geometry>
                <mesh filename="wheelchair/meshes/castor_front_right.STL" />
            </geometry>
            <material name="">
                <color rgba="0.058824 0.058824 0.058824 1" />
            </material>
        </visual>
        <collision>
            <origin rpy="0 0 0" xyz="0 0 0" />
            <geometry>
                <mesh filename="wheelchair/meshes/castor_front_right.STL" />
            </geometry>
        </collision>
    </link>
    <joint name="wheelchair_base_to_castor_front_right" type="fixed">
        <origin rpy="1.5708 0 3.1416" xyz="-0.38799 0.17127 0" />
        <parent link="wheelchair_base_link" />
        <child link="wheelchair_castor_front_right" />
        <axis xyz="0 1 0" />
    </joint>
    <link name="wheelchair_front_wheel_right">
        
<inertial>
            <origin rpy="0 0 0" xyz="-5.5511E-17 -4.3723E-13 1.9429E-16" />
            <mass value="1.1217" />
            <inertia ixx="0.0024847" ixy="8.549E-18" ixz="1.0955E-20" iyy="0.0045217" iyz="-3.8877E-20" izz="0.0024847" />
        </inertial>

        <visual>
            <origin rpy="0 0 0" xyz="0 0 0" />
            <geometry>
                <mesh filename="wheelchair/meshes/front_wheel_right.STL" />
            </geometry>
            <material name="">
                <color rgba="0.89412 0.89412 0.89412 1" />
            </material>
        </visual>
        <collision>
            <origin rpy="0 0 0" xyz="0 0 0" />
            <geometry>
                <mesh filename="wheelchair/meshes/front_wheel_right.STL" />
            </geometry>
        </collision>
    </link>
    <joint name="wheelchair_castor_to_front_wheel_right" type="fixed">
        <origin rpy="1.5708 0 3.1416" xyz="0.026228 -0.0725 0" />
        <parent link="wheelchair_castor_front_right" />
        <child link="wheelchair_front_wheel_right" />
        <axis xyz="0 1 0" />
    </joint>
    <link name="wheelchair_castor_back_right">
        
<inertial>
            <origin rpy="0 0 0" xyz="0.010525 -0.0097266 7.7108E-08" />
            <mass value="0.59378" />
            <inertia ixx="0.0015838" ixy="0.00025285" ixz="2.5396E-10" iyy="0.00070588" iyz="4.8462E-09" izz="0.0012073" />
        </inertial>

        <visual>
            <origin rpy="0 0 0" xyz="0 0 0" />
            <geometry>
                <mesh filename="wheelchair/meshes/castor_back_right.STL" />
            </geometry>
            <material name="">
                <color rgba="0.058824 0.058824 0.058824 1" />
            </material>
        </visual>
        <collision>
            <origin rpy="0 0 0" xyz="0 0 0" />
            <geometry>
                <mesh filename="wheelchair/meshes/castor_back_right.STL" />
            </geometry>
        </collision>
    </link>
    <joint name="wheelchair_base_to_castor_back_right" type="fixed">
        <origin rpy="1.5708 0 0" xyz="0.33036 0.225 0" />
        <parent link="wheelchair_base_link" />
        <child link="wheelchair_castor_back_right" />
        <axis xyz="0 1 0" />
    </joint>
    <link name="wheelchair_back_wheel_right">
        
<inertial>
            <origin rpy="0 0 0" xyz="-5.55111512312578E-17 -4.37178071521771E-13 1.80411241501588E-16" />
            <mass value="1.1217362251687" />
            <inertia ixx="0.00248469116365274" ixy="4.33111862479103E-18" ixz="8.98605873919767E-21" iyy="0.00452169778229441" iyz="-1.22844801633355E-14" izz="0.00248469116365274" />
        </inertial>

        <visual>
            <origin rpy="0 0 0" xyz="0 0 0" />
            <geometry>
                <mesh filename="wheelchair/meshes/back_wheel_right.STL" />
            </geometry>
            <material name="">
                <color rgba="0.894117647058823 0.894117647058823 0.894117647058823 1" />
            </material>
        </visual>
        <collision>
            <origin rpy="0 0 0" xyz="0 0 0" />
            <geometry>
                <mesh filename="wheelchair/meshes/back_wheel_right.STL" />
            </geometry>
        </collision>
    </link>
    <joint name="wheelchair_castor_to_back_wheel_right" type="fixed">
        <origin rpy="1.5708 0 0" xyz="0.026228 -0.0725 0" />
        <parent link="wheelchair_castor_back_right" />
        <child link="wheelchair_back_wheel_right" />
        <axis xyz="0 1 0" />
    </joint>
    <link name="wheelchair_castor_back_left">
        
<inertial>
            <origin rpy="0 0 0" xyz="0.010525 -0.0097266 7.7108E-08" />
            <mass value="0.59378" />
            <inertia ixx="0.0015838" ixy="0.00025285" ixz="2.5396E-10" iyy="0.00070588" iyz="4.8462E-09" izz="0.0012073" />
        </inertial>

        <visual>
            <origin rpy="0 0 0" xyz="0 0 0" />
            <geometry>
                <mesh filename="wheelchair/meshes/castor_back_left.STL" />
            </geometry>
            <material name="">
                <color rgba="0.058824 0.058824 0.058824 1" />
            </material>
        </visual>
        <collision>
            <origin rpy="0 0 0" xyz="0 0 0" />
            <geometry>
                <mesh filename="wheelchair/meshes/castor_back_left.STL" />
            </geometry>
        </collision>
    </link>
    <joint name="wheelchair_base_to_castor_back_left" type="fixed">
        <origin rpy="1.5708 0 0" xyz="0.33036 -0.225 0" />
        <parent link="wheelchair_base_link" />
        <child link="wheelchair_castor_back_left" />
        <axis xyz="0 1 0" />
    </joint>
    <link name="wheelchair_back_wheel_left">
        
<inertial>
            <origin rpy="0 0 0" xyz="0 -4.3721E-13 1.6653E-16" />
            <mass value="1.1217" />
            <inertia ixx="0.0024847" ixy="4.3311E-18" ixz="8.9861E-21" iyy="0.0045217" iyz="-1.2284E-14" izz="0.0024847" />
        </inertial>

        <visual>
            <origin rpy="0 0 0" xyz="0 0 0" />
            <geometry>
                <mesh filename="wheelchair/meshes/back_wheel_left.STL" />
            </geometry>
            <material name="">
                <color rgba="0.89412 0.89412 0.89412 1" />
            </material>
        </visual>
        <collision>
            <origin rpy="0 0 0" xyz="0 0 0" />
            <geometry>
                <mesh filename="wheelchair/meshes/back_wheel_left.STL" />
            </geometry>
        </collision>
    </link>
    <joint name="wheelchair_castor_to_back_wheel_left" type="fixed">
        <origin rpy="1.5708 0 0" xyz="0.026228 -0.0725 0" />
        <parent link="wheelchair_castor_back_left" />
        <child link="wheelchair_back_wheel_left" />
        <axis xyz="0 1 0" />
    </joint>
    <link name="robot_base_link">
        <visual>
            <geometry>
                <mesh filename="ur10e/visual/base.dae" />
            </geometry>
            <material name="LightGrey">
                <color rgba="0.7 0.7 0.7 1.0" />
            </material>
        </visual>
        <collision>
            <geometry>
                <mesh filename="ur10e/collision/base.stl" />
            </geometry>
        </collision>
        
<inertial>
            <mass value="4.0" />
            <origin rpy="0 0 0" xyz="0.0 0.0 0.0" />
            <inertia ixx="0.0061063308908" ixy="0.0" ixz="0.0" iyy="0.0061063308908" iyz="0.0" izz="0.01125" />
        </inertial>

    </link>
    <joint name="robot_shoulder_pan_joint" type="revolute">
        <parent link="robot_base_link" />
        <child link="robot_shoulder_link" />
        <origin rpy="0.0 0.0 -1.57" xyz="0.0 0.0 0.181" />
        <axis xyz="0 0 1" />
        <limit effort="330.0" lower="-6.283185307179586" upper="6.283185307179586" velocity="3.14" />
        <dynamics damping="0.0" friction="0.0" />
    </joint>
    <link name="robot_shoulder_link">
        <visual>
            <geometry>
                <mesh filename="ur10e/visual/shoulder.dae" />
            </geometry>
            <material name="LightGrey">
                <color rgba="0.7 0.7 0.7 1.0" />
            </material>
        </visual>
        <collision>
            <geometry>
                <mesh filename="ur10e/collision/shoulder.stl" />
            </geometry>
        </collision>
        
<inertial>
            <mass value="7.778" />
            <origin rpy="0 0 0" xyz="0.0 0.0 0.0" />
            <inertia ixx="0.03147431257693659" ixy="0.0" ixz="0.0" iyy="0.03147431257693659" iyz="0.0" izz="0.021875624999999996" />
        </inertial>

    </link>
    <joint name="robot_shoulder_lift_joint" type="revolute">
        <parent link="robot_shoulder_link" />
        <child link="robot_upper_arm_link" />
        <origin rpy="0.0 1.5707963267948966 0.0" xyz="0.0 0.176 0.0" />
        <axis xyz="0 1 0" />
        <limit effort="330.0" lower="-6.283185307179586" upper="6.283185307179586" velocity="3.14" />
        <dynamics damping="0.0" friction="0.0" />
    </joint>
    <link name="robot_upper_arm_link">
        <visual>
            <geometry>
                <mesh filename="ur10e/visual/upperarm.dae" />
            </geometry>
            <material name="LightGrey">
                <color rgba="0.7 0.7 0.7 1.0" />
            </material>
        </visual>
        <collision>
            <geometry>
                <mesh filename="ur10e/collision/upperarm.stl" />
            </geometry>
        </collision>
        
<inertial>
            <mass value="12.93" />
            <origin rpy="0 0 0" xyz="0.0 0.0 0.3065" />
            <inertia ixx="0.4230737407704359" ixy="0.0" ixz="0.0" iyy="0.4230737407704359" iyz="0.0" izz="0.03636562499999999" />
        </inertial>

    </link>
    <joint name="robot_elbow_joint" type="revolute">
        <parent link="robot_upper_arm_link" />
        <child link="robot_forearm_link" />
        <origin rpy="0.0 0.0 0.0" xyz="0.0 -0.137 0.613" />
        <axis xyz="0 1 0" />
        <limit effort="150.0" lower="-3.141592653589793" upper="3.141592653589793" velocity="3.14" />
        <dynamics damping="0.0" friction="0.0" />
    </joint>
    <link name="robot_forearm_link">
        <visual>
            <geometry>
                <mesh filename="ur10e/visual/forearm.dae" />
            </geometry>
            <material name="LightGrey">
                <color rgba="0.7 0.7 0.7 1.0" />
            </material>
        </visual>
        <collision>
            <geometry>
                <mesh filename="ur10e/collision/forearm.stl" />
            </geometry>
        </collision>
        
<inertial>
            <mass value="3.87" />
            <origin rpy="0 0 0" xyz="0.0 0.0 0.2855" />
            <inertia ixx="0.11059036576383598" ixy="0.0" ixz="0.0" iyy="0.11059036576383598" iyz="0.0" izz="0.010884375" />
        </inertial>

    </link>
    <joint name="robot_wrist_1_joint" type="revolute">
        <parent link="robot_forearm_link" />
        <child link="robot_wrist_1_link" />
        <origin rpy="0.0 1.57 0.0" xyz=" .0 0.0 0.571" />
        <axis xyz="0 1 0" />
        <limit effort="54.0" lower="-6.283185307179586" upper="6.283185307179586" velocity="6.28" />
        <dynamics damping="0.0" friction="0.0" />
    </joint>
    <link name="robot_wrist_1_link">
        <visual>
            <geometry>
                <mesh filename="ur10e/visual/wrist1.dae" />
            </geometry>
            <material name="LightGrey">
                <color rgba="0.7 0.7 0.7 1.0" />
            </material>
        </visual>
        <collision>
            <geometry>
                <mesh filename="ur10e/collision/wrist1.stl" />
            </geometry>
        </collision>
        
<inertial>
            <mass value="1.96" />
            <origin rpy="0 0 0" xyz="0.0 0.135 0.0" />
            <inertia ixx="0.005108247956699999" ixy="0.0" ixz="0.0" iyy="0.005108247956699999" iyz="0.0" izz="0.005512499999999999" />
        </inertial>

    </link>
    <joint name="robot_wrist_2_joint" type="revolute">
        <parent link="robot_wrist_1_link" />
        <child link="robot_wrist_2_link" />
        <origin rpy="0.0 0.0 0.0" xyz="0.0 0.135 0.0" />
        <axis xyz="0 0 1" />
        <limit effort="54.0" lower="-6.283185307179586" upper="6.283185307179586" velocity="6.28" />
        <dynamics damping="0.0" friction="0.0" />
    </joint>
    <link name="robot_wrist_2_link">
        <visual>
            <geometry>
                <mesh filename="ur10e/visual/wrist2.dae" />
            </geometry>
            <material name="LightGrey">
                <color rgba="0.7 0.7 0.7 1.0" />
            </material>
        </visual>
        <collision>
            <geometry>
                <mesh filename="ur10e/collision/wrist2.stl" />
            </geometry>
        </collision>
        
<inertial>
            <mass value="1.96" />
            <origin rpy="0 0 0" xyz="0.0 0.0 0.12" />
            <inertia ixx="0.005108247956699999" ixy="0.0" ixz="0.0" iyy="0.005108247956699999" iyz="0.0" izz="0.005512499999999999" />
        </inertial>

    </link>
    <joint name="robot_wrist_3_joint" type="revolute">
        <parent link="robot_wrist_2_link" />
        <child link="robot_wrist_3_link" />
        <origin rpy="0.0 -0.785 0.0" xyz="0.0 0.0 0.12" />
        <axis xyz="0 1 0" />
        <limit effort="54.0" lower="-6.283185307179586" upper="6.283185307179586" velocity="6.28" />
        <dynamics damping="0.0" friction="0.0" />
    </joint>
    <link name="robot_wrist_3_link">
        <visual>
            <geometry>
                <mesh filename="ur10e/visual/wrist3.dae" />
            </geometry>
            <material name="LightGrey">
                <color rgba="0.7 0.7 0.7 1.0" />
            </material>
        </visual>
        <collision>
            <geometry>
                <mesh filename="ur10e/collision/wrist3.stl" />
            </geometry>
        </collision>
        
<inertial>
            <mass value="0.202" />
            <origin rpy="0.0 0 0" xyz="0.0 0.092 0.0" />
            <inertia ixx="0.00014434577559500002" ixy="0.0" ixz="0.0" iyy="0.00014434577559500002" iyz="0.0" izz="0.00020452500000000002" />
        </inertial>

    </link>
    <joint name="robot_ee_fixed_joint" type="fixed">
        <parent link="robot_wrist_3_link" />
        <child link="robot_ee_link" />
        <origin rpy="0.0 0.0 1.5707963267948966" xyz="0.0 0.117 0.0" />
    </joint>
    <link name="robot_ee_link">
        <collision>
            <geometry>
                <box size="0.01 0.01 0.01" />
            </geometry>
            <origin rpy="0 0 0" xyz="-0.01 0 0" />
        </collision>
        
<inertial>
            <mass value="0.1" />
            <inertia ixx="0.03" iyy="0.03" izz="0.03" ixy="0.0" ixz="0.0" iyz="0.0" />
        </inertial>

    </link>
    <transmission name="robot_shoulder_pan_trans">
        <type>transmission_interface/SimpleTransmission</type>
        <joint name="robot_shoulder_pan_joint">
            <hardwareInterface>hardware_interface/PositionJointInterface</hardwareInterface>
        </joint>
        <actuator name="robot_shoulder_pan_motor">
            <mechanicalReduction>1</mechanicalReduction>
        </actuator>
    </transmission>
    <transmission name="robot_shoulder_lift_trans">
        <type>transmission_interface/SimpleTransmission</type>
        <joint name="robot_shoulder_lift_joint">
            <hardwareInterface>hardware_interface/PositionJointInterface</hardwareInterface>
        </joint>
        <actuator name="robot_shoulder_lift_motor">
            <mechanicalReduction>1</mechanicalReduction>
        </actuator>
    </transmission>
    <transmission name="robot_elbow_trans">
        <type>transmission_interface/SimpleTransmission</type>
        <joint name="robot_elbow_joint">
            <hardwareInterface>hardware_interface/PositionJointInterface</hardwareInterface>
        </joint>
        <actuator name="robot_elbow_motor">
            <mechanicalReduction>1</mechanicalReduction>
        </actuator>
    </transmission>
    <transmission name="robot_wrist_1_trans">
        <type>transmission_interface/SimpleTransmission</type>
        <joint name="robot_wrist_1_joint">
            <hardwareInterface>hardware_interface/PositionJointInterface</hardwareInterface>
        </joint>
        <actuator name="robot_wrist_1_motor">
            <mechanicalReduction>1</mechanicalReduction>
        </actuator>
    </transmission>
    <transmission name="robot_wrist_2_trans">
        <type>transmission_interface/SimpleTransmission</type>
        <joint name="robot_wrist_2_joint">
            <hardwareInterface>hardware_interface/PositionJointInterface</hardwareInterface>
        </joint>
        <actuator name="robot_wrist_2_motor">
            <mechanicalReduction>1</mechanicalReduction>
        </actuator>
    </transmission>
    <transmission name="robot_wrist_3_trans">
        <type>transmission_interface/SimpleTransmission</type>
        <joint name="robot_wrist_3_joint">
            <hardwareInterface>hardware_interface/PositionJointInterface</hardwareInterface>
        </joint>
        <actuator name="robot_wrist_3_motor">
            <mechanicalReduction>1</mechanicalReduction>
        </actuator>
    </transmission>
    <!-- ROS base_link to UR 'Base' Coordinates transform -->
    <link name="robot_base" />
    <joint name="robot_base_link-base_fixed_joint" type="fixed">
        <!-- NOTE: this rotation is only needed as long as base_link itself is
                 not corrected wrt the real robot (ie: rotated over 180
                 degrees)
      -->
        <origin rpy="0 0 -3.141592653589793" xyz="0 0 0" />
        <parent link="robot_base_link" />
        <child link="robot_base" />
    </joint>
    <!-- Frame coincident with all-zeros TCP on UR controller -->
    <link name="robot_tool0" />
    <joint name="robot_wrist_3_link-tool0_fixed_joint" type="fixed">
        <origin rpy="-1.5707963267948966 -1.57 0" xyz="0 0.117 0" />
        <parent link="robot_wrist_3_link" />
        <child link="robot_tool0" />
    </joint>
    <!-- link list -->
    <link name="gripper_finger_1_link_0">
        <visual>
            <origin rpy="0 0 0" xyz="0.020 0 0" />
            <geometry>
                <mesh filename="robotiq-3f-gripper_articulated/visual/link_0.dae" />
            </geometry>
            <material name="gray">
                <color rgba="0.2 0.2 0.2 1" />
            </material>
        </visual>
        <collision>
            <origin rpy="0 0 0" xyz="0.020 0 0" />
            <geometry>
                <mesh filename="robotiq-3f-gripper_articulated/collision/link_0.STL" />
            </geometry>
            <material name="yellow">
                <color rgba="0 1 1 1" />
            </material>
        </collision>
        
<inertial>
            <origin rpy="0 0 0" xyz="0 0 0" />
            <mass value="0.05" />
            <inertia ixx="0.01" ixy="-0.00002" ixz="0.00001" iyy="0.0008" iyz="0" izz="0.001" />
        </inertial>

    </link>
    <link name="gripper_finger_1_link_1">
        <visual>
            <origin rpy="0 0 -0.52" xyz="0.050 -.028 0" />
            <geometry>
                <mesh filename="robotiq-3f-gripper_articulated/visual/link_1.dae" />
            </geometry>
            <material name="gray" />
        </visual>
        <collision>
            <origin rpy="0 0 -0.52" xyz="0.050 -.028 0" />
            <geometry>
                <mesh filename="robotiq-3f-gripper_articulated/collision/link_1.STL" />
            </geometry>
            <material name="yellow" />
        </collision>
        
<inertial>
            <origin rpy="0 0 0" xyz="0 0 0" />
            <mass value="0.15" />
            <inertia ixx="0.001859" ixy="-0.000376" ixz="0.000028" iyy="0.012756" iyz="0" izz="0.0024" />
        </inertial>

    </link>
    <link name="gripper_finger_1_link_2">
        <!--
            NOTE: This link has an offset in the z-direction based on the models that were
            used to generate grap-it poses.  With the offset below the model appears visually
            correct, but it is suspect.
            -->
        <visual>
            <origin rpy="0 0 0" xyz="0.039 0 0.0075" />
            <geometry>
                <mesh filename="robotiq-3f-gripper_articulated/visual/link_2.dae" />
            </geometry>
            <material name="gray" />
        </visual>
        <collision>
            <origin rpy="0 0 0" xyz="0.039 0 0.0075" />
            <geometry>
                <mesh filename="robotiq-3f-gripper_articulated/collision/link_2.STL" />
            </geometry>
            <material name="yellow" />
        </collision>
        
<inertial>
            <origin rpy="0 0 0" xyz="0 0 0" />
            <mass value="0.15" />
            <inertia ixx="0.001859" ixy="-0.000376" ixz="0.000028" iyy="0.012756" iyz="0" izz="0.0024" />
        </inertial>

    </link>
    <link name="gripper_finger_1_link_3">
        <visual>
            <origin rpy="0 0 0.52" xyz="0 0 0" />
            <geometry>
                <mesh filename="robotiq-3f-gripper_articulated/visual/link_3.dae" />
            </geometry>
            <material name="gray" />
        </visual>
        <collision>
            <origin rpy="0 0 0.52" xyz="0 0 0" />
            <geometry>
                <mesh filename="robotiq-3f-gripper_articulated/collision/link_3.STL" />
            </geometry>
            <material name="yellow" />
        </collision>
        
<inertial>
            <origin rpy="0 0 0" xyz="0 0 0" />
            <mass value="0.05" />
            <inertia ixx="0.001239" ixy="-0.000251" ixz="0.000019" iyy="0.00085" iyz="0" izz="0.001632" />
        </inertial>

    </link>
    <!-- end of link list -->
    <!-- joint list -->
    <joint name="gripper_finger_1_joint_1" type="revolute">
        <parent link="gripper_finger_1_link_0" />
        <child link="gripper_finger_1_link_1" />
        <axis xyz="0 0 1" />
        <origin rpy="0 0 0" xyz="0.020 0 0" />
        <limit effort="100" lower="0.0495" upper="1.2218" velocity="100" />
    </joint>
    <joint name="gripper_finger_1_joint_2" type="revolute">
        <parent link="gripper_finger_1_link_1" />
        <child link="gripper_finger_1_link_2" />
        <axis xyz="0 0 1" />
        <origin rpy="0 0 -0.52" xyz="0.050 -.028 0" />
        <limit effort="100" lower="0.0" upper="1.5708" velocity="100" />
    </joint>
    <joint name="gripper_finger_1_joint_3" type="revolute">
        <parent link="gripper_finger_1_link_2" />
        <child link="gripper_finger_1_link_3" />
        <axis xyz="0 0 1" />
        <origin rpy="0 0 0" xyz="0.039 0 0" />
        <limit effort="100" lower="-1.2217" upper="-0.0523" velocity="100" />
    </joint>
    <!-- end of joint list -->
    <!-- link list -->
    <link name="gripper_finger_2_link_0">
        <visual>
            <origin rpy="0 0 0" xyz="0.020 0 0" />
            <geometry>
                <mesh filename="robotiq-3f-gripper_articulated/visual/link_0.dae" />
            </geometry>
            <material name="gray">
                <color rgba="0.2 0.2 0.2 1" />
            </material>
        </visual>
        <collision>
            <origin rpy="0 0 0" xyz="0.020 0 0" />
            <geometry>
                <mesh filename="robotiq-3f-gripper_articulated/collision/link_0.STL" />
            </geometry>
            <material name="yellow">
                <color rgba="0 1 1 1" />
            </material>
        </collision>
        
<inertial>
            <origin rpy="0 0 0" xyz="0 0 0" />
            <mass value="0.05" />
            <inertia ixx="0.01" ixy="-0.00002" ixz="0.00001" iyy="0.0008" iyz="0" izz="0.001" />
        </inertial>

    </link>
    <link name="gripper_finger_2_link_1">
        <visual>
            <origin rpy="0 0 -0.52" xyz="0.050 -.028 0" />
            <geometry>
                <mesh filename="robotiq-3f-gripper_articulated/visual/link_1.dae" />
            </geometry>
            <material name="gray" />
        </visual>
        <collision>
            <origin rpy="0 0 -0.52" xyz="0.050 -.028 0" />
            <geometry>
                <mesh filename="robotiq-3f-gripper_articulated/collision/link_1.STL" />
            </geometry>
            <material name="yellow" />
        </collision>
        
<inertial>
            <origin rpy="0 0 0" xyz="0 0 0" />
            <mass value="0.15" />
            <inertia ixx="0.001859" ixy="-0.000376" ixz="0.000028" iyy="0.012756" iyz="0" izz="0.0024" />
        </inertial>

    </link>
    <link name="gripper_finger_2_link_2">
        <!--
            NOTE: This link has an offset in the z-direction based on the models that were
            used to generate grap-it poses.  With the offset below the model appears visually
            correct, but it is suspect.
            -->
        <visual>
            <origin rpy="0 0 0" xyz="0.039 0 0.0075" />
            <geometry>
                <mesh filename="robotiq-3f-gripper_articulated/visual/link_2.dae" />
            </geometry>
            <material name="gray" />
        </visual>
        <collision>
            <origin rpy="0 0 0" xyz="0.039 0 0.0075" />
            <geometry>
                <mesh filename="robotiq-3f-gripper_articulated/collision/link_2.STL" />
            </geometry>
            <material name="yellow" />
        </collision>
        
<inertial>
            <origin rpy="0 0 0" xyz="0 0 0" />
            <mass value="0.15" />
            <inertia ixx="0.001859" ixy="-0.000376" ixz="0.000028" iyy="0.012756" iyz="0" izz="0.0024" />
        </inertial>

    </link>
    <link name="gripper_finger_2_link_3">
        <visual>
            <origin rpy="0 0 0.52" xyz="0 0 0" />
            <geometry>
                <mesh filename="robotiq-3f-gripper_articulated/visual/link_3.dae" />
            </geometry>
            <material name="gray" />
        </visual>
        <collision>
            <origin rpy="0 0 0.52" xyz="0 0 0" />
            <geometry>
                <mesh filename="robotiq-3f-gripper_articulated/collision/link_3.STL" />
            </geometry>
            <material name="yellow" />
        </collision>
        
<inertial>
            <origin rpy="0 0 0" xyz="0 0 0" />
            <mass value="0.05" />
            <inertia ixx="0.001239" ixy="-0.000251" ixz="0.000019" iyy="0.00085" iyz="0" izz="0.001632" />
        </inertial>

    </link>
    <!-- end of link list -->
    <!-- joint list -->
    <joint name="gripper_finger_2_joint_1" type="revolute">
        <parent link="gripper_finger_2_link_0" />
        <child link="gripper_finger_2_link_1" />
        <axis xyz="0 0 1" />
        <origin rpy="0 0 0" xyz="0.020 0 0" />
        <limit effort="100" lower="0.0495" upper="1.2218" velocity="100" />
    </joint>
    <joint name="gripper_finger_2_joint_2" type="revolute">
        <parent link="gripper_finger_2_link_1" />
        <child link="gripper_finger_2_link_2" />
        <axis xyz="0 0 1" />
        <origin rpy="0 0 -0.52" xyz="0.050 -.028 0" />
        <limit effort="100" lower="0.0" upper="1.5708" velocity="100" />
    </joint>
    <joint name="gripper_finger_2_joint_3" type="revolute">
        <parent link="gripper_finger_2_link_2" />
        <child link="gripper_finger_2_link_3" />
        <axis xyz="0 0 1" />
        <origin rpy="0 0 0" xyz="0.039 0 0" />
        <limit effort="100" lower="-1.2217" upper="-0.0523" velocity="100" />
    </joint>
    <!-- end of joint list -->
    <!-- link list -->
    <link name="gripper_finger_middle_link_0">
        <visual>
            <origin rpy="0 0 0" xyz="0.020 0 0" />
            <geometry>
                <mesh filename="robotiq-3f-gripper_articulated/visual/link_0.dae" />
            </geometry>
            <material name="gray">
                <color rgba="0.2 0.2 0.2 1" />
            </material>
        </visual>
        <collision>
            <origin rpy="0 0 0" xyz="0.020 0 0" />
            <geometry>
                <mesh filename="robotiq-3f-gripper_articulated/collision/link_0.STL" />
            </geometry>
            <material name="yellow">
                <color rgba="0 1 1 1" />
            </material>
        </collision>
        
<inertial>
            <origin rpy="0 0 0" xyz="0 0 0" />
            <mass value="0.05" />
            <inertia ixx="0.01" ixy="-0.00002" ixz="0.00001" iyy="0.0008" iyz="0" izz="0.001" />
        </inertial>

    </link>
    <link name="gripper_finger_middle_link_1">
        <visual>
            <origin rpy="0 0 -0.52" xyz="0.050 -.028 0" />
            <geometry>
                <mesh filename="robotiq-3f-gripper_articulated/visual/link_1.dae" />
            </geometry>
            <material name="gray" />
        </visual>
        <collision>
            <origin rpy="0 0 -0.52" xyz="0.050 -.028 0" />
            <geometry>
                <mesh filename="robotiq-3f-gripper_articulated/collision/link_1.STL" />
            </geometry>
            <material name="yellow" />
        </collision>
        
<inertial>
            <origin rpy="0 0 0" xyz="0 0 0" />
            <mass value="0.15" />
            <inertia ixx="0.001859" ixy="-0.000376" ixz="0.000028" iyy="0.012756" iyz="0" izz="0.0024" />
        </inertial>

    </link>
    <link name="gripper_finger_middle_link_2">
        <!--
            NOTE: This link has an offset in the z-direction based on the models that were
            used to generate grap-it poses.  With the offset below the model appears visually
            correct, but it is suspect.
            -->
        <visual>
            <origin rpy="0 0 0" xyz="0.039 0 0.0075" />
            <geometry>
                <mesh filename="robotiq-3f-gripper_articulated/visual/link_2.dae" />
            </geometry>
            <material name="gray" />
        </visual>
        <collision>
            <origin rpy="0 0 0" xyz="0.039 0 0.0075" />
            <geometry>
                <mesh filename="robotiq-3f-gripper_articulated/collision/link_2.STL" />
            </geometry>
            <material name="yellow" />
        </collision>
        
<inertial>
            <origin rpy="0 0 0" xyz="0 0 0" />
            <mass value="0.15" />
            <inertia ixx="0.001859" ixy="-0.000376" ixz="0.000028" iyy="0.012756" iyz="0" izz="0.0024" />
        </inertial>

    </link>
    <link name="gripper_finger_middle_link_3">
        <visual>
            <origin rpy="0 0 0.52" xyz="0 0 0" />
            <geometry>
                <mesh filename="robotiq-3f-gripper_articulated/visual/link_3.dae" />
            </geometry>
            <material name="gray" />
        </visual>
        <collision>
            <origin rpy="0 0 0.52" xyz="0 0 0" />
            <geometry>
                <mesh filename="robotiq-3f-gripper_articulated/collision/link_3.STL" />
            </geometry>
            <material name="yellow" />
        </collision>
        
<inertial>
            <origin rpy="0 0 0" xyz="0 0 0" />
            <mass value="0.05" />
            <inertia ixx="0.001239" ixy="-0.000251" ixz="0.000019" iyy="0.00085" iyz="0" izz="0.001632" />
        </inertial>

    </link>
    <!-- end of link list -->
    <!-- joint list -->
    <joint name="gripper_finger_middle_joint_1" type="revolute">
        <parent link="gripper_finger_middle_link_0" />
        <child link="gripper_finger_middle_link_1" />
        <axis xyz="0 0 1" />
        <origin rpy="0 0 0" xyz="0.020 0 0" />
        <limit effort="100" lower="0.0495" upper="1.2218" velocity="100" />
    </joint>
    <joint name="gripper_finger_middle_joint_2" type="revolute">
        <parent link="gripper_finger_middle_link_1" />
        <child link="gripper_finger_middle_link_2" />
        <axis xyz="0 0 1" />
        <origin rpy="0 0 -0.52" xyz="0.050 -.028 0" />
        <limit effort="100" lower="0.0" upper="1.5708" velocity="100" />
    </joint>
    <joint name="gripper_finger_middle_joint_3" type="revolute">
        <parent link="gripper_finger_middle_link_2" />
        <child link="gripper_finger_middle_link_3" />
        <axis xyz="0 0 1" />
        <origin rpy="0 0 0" xyz="0.039 0 0" />
        <limit effort="100" lower="-1.2217" upper="-0.0523" velocity="100" />
    </joint>
    <!-- end of joint list -->
    <!-- link list -->
    <link name="gripper_palm">
        <visual>
            <geometry>
                <mesh filename="robotiq-3f-gripper_articulated/visual/palm.dae" />
            </geometry>
            <material name="gray">
                <color rgba="0.2 0.2 0.2 1" />
            </material>
        </visual>
        <collision>
            <geometry>
                <mesh filename="robotiq-3f-gripper_articulated/collision/palm.STL" />
            </geometry>
            <material name="yellow">
                <color rgba="0 1 1 1" />
            </material>
        </collision>
        
<inertial>
            <mass value="0.1" />
            <inertia ixx="0.03" iyy="0.03" izz="0.03" ixy="0.0" ixz="0.0" iyz="0.0" />
        </inertial>

    </link>
    <link name="gripper_tool0" />
    
<inertial>
        <origin rpy="0 0 0" xyz="0 0 0" />
        <mass value="1.3" />
        <inertia ixx="0.006012" ixy="0.000079" ixz="-0.00024" iyy="0.012892" iyz="0" izz="0.002435" />
    </inertial>

    <!-- end of link list -->
    <!-- joint list -->
    <joint name="gripper_palm_finger_1_joint" type="fixed">
        <parent link="gripper_palm" />
        <child link="gripper_finger_1_link_0" />
        <axis xyz="0 1 0" />
        <origin rpy="0 3.1416 -1.57" xyz="-0.0455 0.0214 0.036" />
        <limit effort="100" lower="-0.1784" upper="0.192" velocity="100" />
    </joint>
    <joint name="gripper_palm_finger_2_joint" type="fixed">
        <parent link="gripper_palm" />
        <child link="gripper_finger_2_link_0" />
        <axis xyz="0 1 0" />
        <origin rpy="0 3.1416 -1.57" xyz="-0.0455 0.0214 -0.036" />
        <limit effort="100" lower="-0.192" upper="0.1784" velocity="100" />
    </joint>
    <joint name="gripper_palm_finger_middle_joint" type="fixed">
        <parent link="gripper_palm" />
        <child link="gripper_finger_middle_link_0" />
        <axis xyz="0 0 1" />
        <origin rpy="0 0 1.57" xyz="0.0455 0.0214 0" />
    </joint>
    <joint name="gripper_palm_tool0" type="fixed">
        <parent link="gripper_palm" />
        <child link="gripper_tool0" />
        <origin rpy="0 0 1.5707" xyz="0.0 0.0875 0.0" />
    </joint>
    <!-- end of joint list -->
    <!-- attach gripper to UR10e -->
    <joint name="wheelchair_base-ur10e_base_link" type="fixed">
        <origin rpy="0 0 0" xyz="0 0 0.3" />
        <parent link="wheelchair_base_link" />
        <child link="robot_base_link" />
    </joint>
    <!-- attach gripper to UR10e -->
    <joint name="ee_link-robotiq_3f_base_link" type="fixed">
        <origin rpy="0 0 -1.5708" xyz="0 0 0" />
        <parent link="robot_ee_link" />
        <child link="gripper_palm" />
    </joint>
    <transmission name="trans_wheelchair_base_drive_wheel_right">
        <type>transmission_interface/SimpleTransmission</type>
        <joint name="wheelchair_base_drive_wheel_right">
            <hardwareInterface>hardware_interface/EffortJointInterface</hardwareInterface>
        </joint>
        <actuator name="wheelchair_base_drive_wheel_right_motor">
            <hardwareInterface>hardware_interface/EffortJointInterface</hardwareInterface>
            <mechanicalReduction>1</mechanicalReduction>
        </actuator>
    </transmission>
    <transmission name="trans_wheelchair_base_drive_wheel_left">
        <type>transmission_interface/SimpleTransmission</type>
        <joint name="wheelchair_base_drive_wheel_left">
            <hardwareInterface>hardware_interface/EffortJointInterface</hardwareInterface>
        </joint>
        <actuator name="wheelchair_base_drive_wheel_left_motor">
            <hardwareInterface>hardware_interface/EffortJointInterface</hardwareInterface>
            <mechanicalReduction>1</mechanicalReduction>
        </actuator>
    </transmission>
    <transmission name="trans_wheelchair_base_to_castor_front_left">
        <type>transmission_interface/SimpleTransmission</type>
        <joint name="wheelchair_base_to_castor_front_left">
            <hardwareInterface>hardware_interface/EffortJointInterface</hardwareInterface>
        </joint>
        <actuator name="wheelchair_base_to_castor_front_left_motor">
            <hardwareInterface>hardware_interface/EffortJointInterface</hardwareInterface>
            <mechanicalReduction>1</mechanicalReduction>
        </actuator>
    </transmission>
    <transmission name="trans_wheelchair_castor_to_front_wheel_left">
        <type>transmission_interface/SimpleTransmission</type>
        <joint name="wheelchair_castor_to_front_wheel_left">
            <hardwareInterface>hardware_interface/EffortJointInterface</hardwareInterface>
        </joint>
        <actuator name="wheelchair_castor_to_front_wheel_left_motor">
            <hardwareInterface>hardware_interface/EffortJointInterface</hardwareInterface>
            <mechanicalReduction>1</mechanicalReduction>
        </actuator>
    </transmission>
    <transmission name="trans_wheelchair_base_to_castor_front_right">
        <type>transmission_interface/SimpleTransmission</type>
        <joint name="wheelchair_base_to_castor_front_right">
            <hardwareInterface>hardware_interface/EffortJointInterface</hardwareInterface>
        </joint>
        <actuator name="wheelchair_base_to_castor_front_right_motor">
            <hardwareInterface>hardware_interface/EffortJointInterface</hardwareInterface>
            <mechanicalReduction>1</mechanicalReduction>
        </actuator>
    </transmission>
    <transmission name="trans_wheelchair_castor_to_front_wheel_right">
        <type>transmission_interface/SimpleTransmission</type>
        <joint name="wheelchair_castor_to_front_wheel_right">
            <hardwareInterface>hardware_interface/EffortJointInterface</hardwareInterface>
        </joint>
        <actuator name="wheelchair_castor_to_front_wheel_right_motor">
            <hardwareInterface>hardware_interface/EffortJointInterface</hardwareInterface>
            <mechanicalReduction>1</mechanicalReduction>
        </actuator>
    </transmission>
    <transmission name="trans_wheelchair_base_to_castor_back_right">
        <type>transmission_interface/SimpleTransmission</type>
        <joint name="wheelchair_base_to_castor_back_right">
            <hardwareInterface>hardware_interface/EffortJointInterface</hardwareInterface>
        </joint>
        <actuator name="wheelchair_base_to_castor_back_right_motor">
            <hardwareInterface>hardware_interface/EffortJointInterface</hardwareInterface>
            <mechanicalReduction>1</mechanicalReduction>
        </actuator>
    </transmission>
    <transmission name="trans_wheelchair_castor_to_back_wheel_right">
        <type>transmission_interface/SimpleTransmission</type>
        <joint name="wheelchair_castor_to_back_wheel_right">
            <hardwareInterface>hardware_interface/EffortJointInterface</hardwareInterface>
        </joint>
        <actuator name="wheelchair_castor_to_back_wheel_right_motor">
            <hardwareInterface>hardware_interface/EffortJointInterface</hardwareInterface>
            <mechanicalReduction>1</mechanicalReduction>
        </actuator>
    </transmission>
    <transmission name="trans_wheelchair_base_to_castor_back_left">
        <type>transmission_interface/SimpleTransmission</type>
        <joint name="wheelchair_base_to_castor_back_left">
            <hardwareInterface>hardware_interface/EffortJointInterface</hardwareInterface>
        </joint>
        <actuator name="wheelchair_base_to_castor_back_left_motor">
            <hardwareInterface>hardware_interface/EffortJointInterface</hardwareInterface>
            <mechanicalReduction>1</mechanicalReduction>
        </actuator>
    </transmission>
    <transmission name="trans_wheelchair_castor_to_back_wheel_left">
        <type>transmission_interface/SimpleTransmission</type>
        <joint name="wheelchair_castor_to_back_wheel_left">
            <hardwareInterface>hardware_interface/EffortJointInterface</hardwareInterface>
        </joint>
        <actuator name="wheelchair_castor_to_back_wheel_left_motor">
            <hardwareInterface>hardware_interface/EffortJointInterface</hardwareInterface>
            <mechanicalReduction>1</mechanicalReduction>
        </actuator>
    </transmission>
    <transmission name="trans_robot_shoulder_pan_joint">
        <type>transmission_interface/SimpleTransmission</type>
        <joint name="robot_shoulder_pan_joint">
            <hardwareInterface>hardware_interface/EffortJointInterface</hardwareInterface>
        </joint>
        <actuator name="robot_shoulder_pan_joint_motor">
            <hardwareInterface>hardware_interface/EffortJointInterface</hardwareInterface>
            <mechanicalReduction>1</mechanicalReduction>
        </actuator>
    </transmission>
    <transmission name="trans_robot_shoulder_lift_joint">
        <type>transmission_interface/SimpleTransmission</type>
        <joint name="robot_shoulder_lift_joint">
            <hardwareInterface>hardware_interface/EffortJointInterface</hardwareInterface>
        </joint>
        <actuator name="robot_shoulder_lift_joint_motor">
            <hardwareInterface>hardware_interface/EffortJointInterface</hardwareInterface>
            <mechanicalReduction>1</mechanicalReduction>
        </actuator>
    </transmission>
    <transmission name="trans_robot_elbow_joint">
        <type>transmission_interface/SimpleTransmission</type>
        <joint name="robot_elbow_joint">
            <hardwareInterface>hardware_interface/EffortJointInterface</hardwareInterface>
        </joint>
        <actuator name="robot_elbow_joint_motor">
            <hardwareInterface>hardware_interface/EffortJointInterface</hardwareInterface>
            <mechanicalReduction>1</mechanicalReduction>
        </actuator>
    </transmission>
    <transmission name="trans_robot_wrist_1_joint">
        <type>transmission_interface/SimpleTransmission</type>
        <joint name="robot_wrist_1_joint">
            <hardwareInterface>hardware_interface/EffortJointInterface</hardwareInterface>
        </joint>
        <actuator name="robot_wrist_1_joint_motor">
            <hardwareInterface>hardware_interface/EffortJointInterface</hardwareInterface>
            <mechanicalReduction>1</mechanicalReduction>
        </actuator>
    </transmission>
    <transmission name="trans_robot_wrist_2_joint">
        <type>transmission_interface/SimpleTransmission</type>
        <joint name="robot_wrist_2_joint">
            <hardwareInterface>hardware_interface/EffortJointInterface</hardwareInterface>
        </joint>
        <actuator name="robot_wrist_2_joint_motor">
            <hardwareInterface>hardware_interface/EffortJointInterface</hardwareInterface>
            <mechanicalReduction>1</mechanicalReduction>
        </actuator>
    </transmission>
    <transmission name="trans_robot_wrist_3_joint">
        <type>transmission_interface/SimpleTransmission</type>
        <joint name="robot_wrist_3_joint">
            <hardwareInterface>hardware_interface/EffortJointInterface</hardwareInterface>
        </joint>
        <actuator name="robot_wrist_3_joint_motor">
            <hardwareInterface>hardware_interface/EffortJointInterface</hardwareInterface>
            <mechanicalReduction>1</mechanicalReduction>
        </actuator>
    </transmission>
    <transmission name="trans_gripper_finger_1_joint_1">
        <type>transmission_interface/SimpleTransmission</type>
        <joint name="gripper_finger_1_joint_1">
            <hardwareInterface>hardware_interface/EffortJointInterface</hardwareInterface>
        </joint>
        <actuator name="gripper_finger_1_joint_1_motor">
            <hardwareInterface>hardware_interface/EffortJointInterface</hardwareInterface>
            <mechanicalReduction>1</mechanicalReduction>
        </actuator>
    </transmission>
    <transmission name="trans_gripper_finger_1_joint_2">
        <type>transmission_interface/SimpleTransmission</type>
        <joint name="gripper_finger_1_joint_2">
            <hardwareInterface>hardware_interface/EffortJointInterface</hardwareInterface>
        </joint>
        <actuator name="gripper_finger_1_joint_2_motor">
            <hardwareInterface>hardware_interface/EffortJointInterface</hardwareInterface>
            <mechanicalReduction>1</mechanicalReduction>
        </actuator>
    </transmission>
    <transmission name="trans_gripper_finger_1_joint_3">
        <type>transmission_interface/SimpleTransmission</type>
        <joint name="gripper_finger_1_joint_3">
            <hardwareInterface>hardware_interface/EffortJointInterface</hardwareInterface>
        </joint>
        <actuator name="gripper_finger_1_joint_3_motor">
            <hardwareInterface>hardware_interface/EffortJointInterface</hardwareInterface>
            <mechanicalReduction>1</mechanicalReduction>
        </actuator>
    </transmission>
    <transmission name="trans_gripper_finger_2_joint_1">
        <type>transmission_interface/SimpleTransmission</type>
        <joint name="gripper_finger_2_joint_1">
            <hardwareInterface>hardware_interface/EffortJointInterface</hardwareInterface>
        </joint>
        <actuator name="gripper_finger_2_joint_1_motor">
            <hardwareInterface>hardware_interface/EffortJointInterface</hardwareInterface>
            <mechanicalReduction>1</mechanicalReduction>
        </actuator>
    </transmission>
    <transmission name="trans_gripper_finger_2_joint_2">
        <type>transmission_interface/SimpleTransmission</type>
        <joint name="gripper_finger_2_joint_2">
            <hardwareInterface>hardware_interface/EffortJointInterface</hardwareInterface>
        </joint>
        <actuator name="gripper_finger_2_joint_2_motor">
            <hardwareInterface>hardware_interface/EffortJointInterface</hardwareInterface>
            <mechanicalReduction>1</mechanicalReduction>
        </actuator>
    </transmission>
    <transmission name="trans_gripper_finger_2_joint_3">
        <type>transmission_interface/SimpleTransmission</type>
        <joint name="gripper_finger_2_joint_3">
            <hardwareInterface>hardware_interface/EffortJointInterface</hardwareInterface>
        </joint>
        <actuator name="gripper_finger_2_joint_3_motor">
            <hardwareInterface>hardware_interface/EffortJointInterface</hardwareInterface>
            <mechanicalReduction>1</mechanicalReduction>
        </actuator>
    </transmission>
    <transmission name="trans_gripper_finger_middle_joint_1">
        <type>transmission_interface/SimpleTransmission</type>
        <joint name="gripper_finger_middle_joint_1">
            <hardwareInterface>hardware_interface/EffortJointInterface</hardwareInterface>
        </joint>
        <actuator name="gripper_finger_middle_joint_1_motor">
            <hardwareInterface>hardware_interface/EffortJointInterface</hardwareInterface>
            <mechanicalReduction>1</mechanicalReduction>
        </actuator>
    </transmission>
    <transmission name="trans_gripper_finger_middle_joint_2">
        <type>transmission_interface/SimpleTransmission</type>
        <joint name="gripper_finger_middle_joint_2">
            <hardwareInterface>hardware_interface/EffortJointInterface</hardwareInterface>
        </joint>
        <actuator name="gripper_finger_middle_joint_2_motor">
            <hardwareInterface>hardware_interface/EffortJointInterface</hardwareInterface>
            <mechanicalReduction>1</mechanicalReduction>
        </actuator>
    </transmission>
    <transmission name="trans_gripper_finger_middle_joint_3">
        <type>transmission_interface/SimpleTransmission</type>
        <joint name="gripper_finger_middle_joint_3">
            <hardwareInterface>hardware_interface/EffortJointInterface</hardwareInterface>
        </joint>
        <actuator name="gripper_finger_middle_joint_3_motor">
            <hardwareInterface>hardware_interface/EffortJointInterface</hardwareInterface>
            <mechanicalReduction>1</mechanicalReduction>
        </actuator>
    </transmission>
    <transmission name="trans_gripper_palm_finger_1_joint">
        <type>transmission_interface/SimpleTransmission</type>
        <joint name="gripper_palm_finger_1_joint">
            <hardwareInterface>hardware_interface/EffortJointInterface</hardwareInterface>
        </joint>
        <actuator name="gripper_palm_finger_1_joint_motor">
            <hardwareInterface>hardware_interface/EffortJointInterface</hardwareInterface>
            <mechanicalReduction>1</mechanicalReduction>
        </actuator>
    </transmission>
    <transmission name="trans_gripper_palm_finger_2_joint">
        <type>transmission_interface/SimpleTransmission</type>
        <joint name="gripper_palm_finger_2_joint">
            <hardwareInterface>hardware_interface/EffortJointInterface</hardwareInterface>
        </joint>
        <actuator name="gripper_palm_finger_2_joint_motor">
            <hardwareInterface>hardware_interface/EffortJointInterface</hardwareInterface>
            <mechanicalReduction>1</mechanicalReduction>
        </actuator>
    </transmission>
</robot>